[2024-02-17 15:52:40,306: INFO: main: Welcome to Our custom logging]
[2024-02-23 17:37:15,552: INFO: main: >>>>>> stage Data Ingestion stage started <<<<<<]
[2024-02-23 17:37:15,557: INFO: common: yaml file: config/config.yaml loaded successfully]
[2024-02-23 17:37:15,559: INFO: common: yaml file: params.yaml loaded successfully]
[2024-02-23 17:37:15,560: ERROR: main: yaml file is empty]
Traceback (most recent call last):
  File "/Users/pardhu/Documents/ML_Projects/NLP_Text_Summarizer/src/textSummarizer/utils/common.py", line 30, in read_yaml
    return ConfigBox(content)
  File "box/box.py", line 259, in box.box.Box.__init__
box.exceptions.BoxValueError: First argument must be mapping or iterable

During handling of the above exception, another exception occurred:

Traceback (most recent call last):
  File "main.py", line 8, in <module>
    data_ingestion.main()
  File "/Users/pardhu/Documents/ML_Projects/NLP_Text_Summarizer/src/textSummarizer/pipeline/stage_01_data_ingestion.py", line 11, in main
    config = ConfigurationManager()
  File "/Users/pardhu/Documents/ML_Projects/NLP_Text_Summarizer/src/textSummarizer/config/configuration.py", line 12, in __init__
    self.params = read_yaml(params_filepath)
  File "/Users/pardhu/anaconda3/envs/textS/lib/python3.8/site-packages/ensure/main.py", line 849, in __call__
    return_val = self.f(*args, **kwargs)
  File "/Users/pardhu/Documents/ML_Projects/NLP_Text_Summarizer/src/textSummarizer/utils/common.py", line 32, in read_yaml
    raise ValueError("yaml file is empty")
ValueError: yaml file is empty
[2024-02-23 17:41:47,483: INFO: main: >>>>>> stage Data Ingestion stage started <<<<<<]
[2024-02-23 17:41:47,489: INFO: common: yaml file: config/config.yaml loaded successfully]
[2024-02-23 17:41:47,491: INFO: common: yaml file: params.yaml loaded successfully]
[2024-02-23 17:41:47,492: ERROR: main: yaml file is empty]
Traceback (most recent call last):
  File "/Users/pardhu/Documents/ML_Projects/NLP_Text_Summarizer/src/textSummarizer/utils/common.py", line 30, in read_yaml
    return ConfigBox(content)
  File "box/box.py", line 259, in box.box.Box.__init__
box.exceptions.BoxValueError: First argument must be mapping or iterable

During handling of the above exception, another exception occurred:

Traceback (most recent call last):
  File "main.py", line 8, in <module>
    data_ingestion.main()
  File "/Users/pardhu/Documents/ML_Projects/NLP_Text_Summarizer/src/textSummarizer/pipeline/stage_01_data_ingestion.py", line 11, in main
    config = ConfigurationManager()
  File "/Users/pardhu/Documents/ML_Projects/NLP_Text_Summarizer/src/textSummarizer/config/configuration.py", line 12, in __init__
    self.params = read_yaml(params_filepath)
  File "/Users/pardhu/anaconda3/envs/textS/lib/python3.8/site-packages/ensure/main.py", line 849, in __call__
    return_val = self.f(*args, **kwargs)
  File "/Users/pardhu/Documents/ML_Projects/NLP_Text_Summarizer/src/textSummarizer/utils/common.py", line 32, in read_yaml
    raise ValueError("yaml file is empty")
ValueError: yaml file is empty
[2024-02-23 17:44:56,026: INFO: main: >>>>>> stage Data Ingestion stage started <<<<<<]
[2024-02-23 17:44:56,032: INFO: common: yaml file: config/config.yaml loaded successfully]
[2024-02-23 17:44:56,036: INFO: common: yaml file: params.yaml loaded successfully]
[2024-02-23 17:44:56,036: ERROR: main: yaml file is empty]
Traceback (most recent call last):
  File "/Users/pardhu/Documents/ML_Projects/NLP_Text_Summarizer/src/textSummarizer/utils/common.py", line 30, in read_yaml
    return ConfigBox(content)
  File "box/box.py", line 259, in box.box.Box.__init__
box.exceptions.BoxValueError: First argument must be mapping or iterable

During handling of the above exception, another exception occurred:

Traceback (most recent call last):
  File "main.py", line 8, in <module>
    data_ingestion.main()
  File "/Users/pardhu/Documents/ML_Projects/NLP_Text_Summarizer/src/textSummarizer/pipeline/stage_01_data_ingestion.py", line 11, in main
    config = ConfigurationManager()
  File "/Users/pardhu/Documents/ML_Projects/NLP_Text_Summarizer/src/textSummarizer/config/configuration.py", line 12, in __init__
    self.params = read_yaml(params_filepath)
  File "/Users/pardhu/anaconda3/envs/textS/lib/python3.8/site-packages/ensure/main.py", line 849, in __call__
    return_val = self.f(*args, **kwargs)
  File "/Users/pardhu/Documents/ML_Projects/NLP_Text_Summarizer/src/textSummarizer/utils/common.py", line 32, in read_yaml
    raise ValueError("yaml file is empty")
ValueError: yaml file is empty
[2024-02-23 17:57:01,341: INFO: main: >>>>>> stage Data Ingestion stage started <<<<<<]
[2024-02-23 17:57:01,345: INFO: common: yaml file: config/config.yaml loaded successfully]
[2024-02-23 17:57:01,348: INFO: common: yaml file: params.yaml loaded successfully]
[2024-02-23 17:57:01,348: ERROR: main: yaml file is empty]
Traceback (most recent call last):
  File "/Users/pardhu/Documents/ML_Projects/NLP_Text_Summarizer/src/textSummarizer/utils/common.py", line 30, in read_yaml
    return ConfigBox(content)
  File "box/box.py", line 259, in box.box.Box.__init__
box.exceptions.BoxValueError: First argument must be mapping or iterable

During handling of the above exception, another exception occurred:

Traceback (most recent call last):
  File "main.py", line 8, in <module>
    data_ingestion.main()
  File "/Users/pardhu/Documents/ML_Projects/NLP_Text_Summarizer/src/textSummarizer/pipeline/stage_01_data_ingestion.py", line 11, in main
    config = ConfigurationManager()
  File "/Users/pardhu/Documents/ML_Projects/NLP_Text_Summarizer/src/textSummarizer/config/configuration.py", line 12, in __init__
    self.params = read_yaml(params_filepath)
  File "/Users/pardhu/anaconda3/envs/textS/lib/python3.8/site-packages/ensure/main.py", line 849, in __call__
    return_val = self.f(*args, **kwargs)
  File "/Users/pardhu/Documents/ML_Projects/NLP_Text_Summarizer/src/textSummarizer/utils/common.py", line 32, in read_yaml
    raise ValueError("yaml file is empty")
ValueError: yaml file is empty
[2024-02-23 17:58:11,334: INFO: main: >>>>>> stage Data Ingestion stage started <<<<<<]
[2024-02-23 17:58:11,338: INFO: common: yaml file: config/config.yaml loaded successfully]
[2024-02-23 17:58:11,342: INFO: common: yaml file: params.yaml loaded successfully]
[2024-02-23 17:58:11,342: ERROR: main: yaml file is empty]
Traceback (most recent call last):
  File "/Users/pardhu/Documents/ML_Projects/NLP_Text_Summarizer/src/textSummarizer/utils/common.py", line 31, in read_yaml
    return ConfigBox(content)
  File "box/box.py", line 259, in box.box.Box.__init__
box.exceptions.BoxValueError: First argument must be mapping or iterable

During handling of the above exception, another exception occurred:

Traceback (most recent call last):
  File "main.py", line 8, in <module>
    data_ingestion.main()
  File "/Users/pardhu/Documents/ML_Projects/NLP_Text_Summarizer/src/textSummarizer/pipeline/stage_01_data_ingestion.py", line 11, in main
    config = ConfigurationManager()
  File "/Users/pardhu/Documents/ML_Projects/NLP_Text_Summarizer/src/textSummarizer/config/configuration.py", line 12, in __init__
    self.params = read_yaml(params_filepath)
  File "/Users/pardhu/anaconda3/envs/textS/lib/python3.8/site-packages/ensure/main.py", line 849, in __call__
    return_val = self.f(*args, **kwargs)
  File "/Users/pardhu/Documents/ML_Projects/NLP_Text_Summarizer/src/textSummarizer/utils/common.py", line 33, in read_yaml
    raise ValueError("yaml file is empty")
ValueError: yaml file is empty
[2024-02-23 17:59:36,162: INFO: main: >>>>>> stage Data Ingestion stage started <<<<<<]
[2024-02-23 17:59:36,167: INFO: common: yaml file: config/config.yaml loaded successfully]
[2024-02-23 17:59:36,170: INFO: common: yaml file: params.yaml loaded successfully]
[2024-02-23 17:59:36,171: INFO: common: created directory at: artifacts]
[2024-02-23 17:59:36,171: INFO: common: created directory at: artifacts/data_ingestion]
[2024-02-23 17:59:39,066: INFO: data_ingestion: artifacts/data_ingestion/data.zip download! with following info: 
Connection: close
Content-Length: 8274362
Cache-Control: max-age=300
Content-Security-Policy: default-src 'none'; style-src 'unsafe-inline'; sandbox
Content-Type: application/zip
ETag: "6067cb05b4d8701b71f8c029f97cd00c5bc1144cb94632e0db74389cc0c2ab84"
Strict-Transport-Security: max-age=31536000
X-Content-Type-Options: nosniff
X-Frame-Options: deny
X-XSS-Protection: 1; mode=block
X-GitHub-Request-Id: B78A:74426:506064:64DEF8:65D92355
Accept-Ranges: bytes
Date: Fri, 23 Feb 2024 22:59:37 GMT
Via: 1.1 varnish
X-Served-By: cache-bos4637-BOS
X-Cache: MISS
X-Cache-Hits: 0
X-Timer: S1708729177.684776,VS0,VE331
Vary: Authorization,Accept-Encoding,Origin
Access-Control-Allow-Origin: *
Cross-Origin-Resource-Policy: cross-origin
X-Fastly-Request-ID: 3c85ce91a96df287d7dd874de6eb6005126a18be
Expires: Fri, 23 Feb 2024 23:04:37 GMT
Source-Age: 0

]
[2024-02-23 17:59:39,328: INFO: main: >>>>>> stage Data Ingestion stage completed <<<<<<

x==========x]
[2024-02-24 15:43:34,922: INFO: main: >>>>>> stage Data Ingestion stage started <<<<<<]
[2024-02-24 15:43:34,927: INFO: common: yaml file: config/config.yaml loaded successfully]
[2024-02-24 15:43:34,933: INFO: common: yaml file: params.yaml loaded successfully]
[2024-02-24 15:43:34,934: INFO: common: created directory at: artifacts]
[2024-02-24 15:43:34,934: INFO: common: created directory at: artifacts/data_ingestion]
[2024-02-24 15:43:37,288: INFO: data_ingestion: artifacts/data_ingestion/data.zip download! with following info: 
Connection: close
Content-Length: 8274362
Cache-Control: max-age=300
Content-Security-Policy: default-src 'none'; style-src 'unsafe-inline'; sandbox
Content-Type: application/zip
ETag: "6067cb05b4d8701b71f8c029f97cd00c5bc1144cb94632e0db74389cc0c2ab84"
Strict-Transport-Security: max-age=31536000
X-Content-Type-Options: nosniff
X-Frame-Options: deny
X-XSS-Protection: 1; mode=block
X-GitHub-Request-Id: DDAE:4C63:740FA8:8B3089:65DA54F4
Accept-Ranges: bytes
Date: Sat, 24 Feb 2024 20:43:35 GMT
Via: 1.1 varnish
X-Served-By: cache-bos4686-BOS
X-Cache: MISS
X-Cache-Hits: 0
X-Timer: S1708807416.782591,VS0,VE108
Vary: Authorization,Accept-Encoding,Origin
Access-Control-Allow-Origin: *
Cross-Origin-Resource-Policy: cross-origin
X-Fastly-Request-ID: 82ee4ab59aa0982d8200e08eb964d7c1bf720943
Expires: Sat, 24 Feb 2024 20:48:35 GMT
Source-Age: 0

]
[2024-02-24 15:43:37,531: INFO: main: >>>>>> stage Data Ingestion stage completed <<<<<<

x==========x]
[2024-02-24 15:43:37,531: INFO: main: >>>>>> stage Data Validation stage started <<<<<<]
[2024-02-24 15:43:37,535: INFO: common: yaml file: config/config.yaml loaded successfully]
[2024-02-24 15:43:37,536: INFO: common: yaml file: params.yaml loaded successfully]
[2024-02-24 15:43:37,537: INFO: common: created directory at: artifacts]
[2024-02-24 15:43:37,537: INFO: common: created directory at: artifacts/data_validation]
[2024-02-24 15:43:37,539: INFO: main: >>>>>> stage Data Validation stage completed <<<<<<

x==========x]
[2024-02-24 16:06:09,755: INFO: config: PyTorch version 2.2.0 available.]
[2024-02-24 16:06:58,589: INFO: config: PyTorch version 2.2.0 available.]
[2024-02-24 16:07:21,858: INFO: config: PyTorch version 2.2.0 available.]
[2024-02-24 16:08:10,463: INFO: config: PyTorch version 2.2.0 available.]
[2024-02-24 16:08:11,808: INFO: main: >>>>>> stage Data Ingestion stage started <<<<<<]
[2024-02-24 16:08:11,812: INFO: common: yaml file: config/config.yaml loaded successfully]
[2024-02-24 16:08:11,816: INFO: common: yaml file: params.yaml loaded successfully]
[2024-02-24 16:08:11,817: INFO: common: created directory at: artifacts]
[2024-02-24 16:08:11,817: INFO: common: created directory at: artifacts/data_ingestion]
[2024-02-24 16:08:15,551: INFO: data_ingestion: artifacts/data_ingestion/data.zip download! with following info: 
Connection: close
Content-Length: 8274362
Cache-Control: max-age=300
Content-Security-Policy: default-src 'none'; style-src 'unsafe-inline'; sandbox
Content-Type: application/zip
ETag: "6067cb05b4d8701b71f8c029f97cd00c5bc1144cb94632e0db74389cc0c2ab84"
Strict-Transport-Security: max-age=31536000
X-Content-Type-Options: nosniff
X-Frame-Options: deny
X-XSS-Protection: 1; mode=block
X-GitHub-Request-Id: DDAE:4C63:740FA8:8B3089:65DA54F4
Accept-Ranges: bytes
Date: Sat, 24 Feb 2024 21:08:13 GMT
Via: 1.1 varnish
X-Served-By: cache-bos4665-BOS
X-Cache: HIT
X-Cache-Hits: 0
X-Timer: S1708808894.567998,VS0,VE106
Vary: Authorization,Accept-Encoding,Origin
Access-Control-Allow-Origin: *
Cross-Origin-Resource-Policy: cross-origin
X-Fastly-Request-ID: f2da87a8e38d67a28fea4a63c8971539fbc45169
Expires: Sat, 24 Feb 2024 21:13:13 GMT
Source-Age: 0

]
[2024-02-24 16:08:15,750: INFO: main: >>>>>> stage Data Ingestion stage completed <<<<<<

x==========x]
[2024-02-24 16:08:15,750: INFO: main: >>>>>> stage Data Validation stage started <<<<<<]
[2024-02-24 16:08:15,753: INFO: common: yaml file: config/config.yaml loaded successfully]
[2024-02-24 16:08:15,755: INFO: common: yaml file: params.yaml loaded successfully]
[2024-02-24 16:08:15,755: INFO: common: created directory at: artifacts]
[2024-02-24 16:08:15,755: INFO: common: created directory at: artifacts/data_validation]
[2024-02-24 16:08:15,757: INFO: main: >>>>>> stage Data Validation stage completed <<<<<<

x==========x]
[2024-02-24 16:08:15,757: INFO: main: >>>>>> stage Data Transformation stage started <<<<<<]
[2024-02-24 16:08:15,760: INFO: common: yaml file: config/config.yaml loaded successfully]
[2024-02-24 16:08:15,761: INFO: common: yaml file: params.yaml loaded successfully]
[2024-02-24 16:08:15,762: INFO: common: created directory at: artifacts]
[2024-02-24 16:08:15,762: INFO: common: created directory at: artifacts/data_validation]
[2024-02-24 16:08:15,762: ERROR: main: "'ConfigBox' object has no attribute 'data_path'"]
Traceback (most recent call last):
  File "box/box.py", line 503, in box.box.Box.__getitem__
KeyError: 'data_path'

The above exception was the direct cause of the following exception:

Traceback (most recent call last):
  File "box/box.py", line 536, in box.box.Box.__getattr__
  File "box/box.py", line 524, in box.box.Box.__getitem__
box.exceptions.BoxKeyError: "'data_path'"

During handling of the above exception, another exception occurred:

Traceback (most recent call last):
  File "box/box.py", line 538, in box.box.Box.__getattr__
AttributeError: 'ConfigBox' object has no attribute 'data_path'

The above exception was the direct cause of the following exception:

Traceback (most recent call last):
  File "box/config_box.py", line 28, in box.config_box.ConfigBox.__getattr__
  File "box/box.py", line 552, in box.box.Box.__getattr__
box.exceptions.BoxKeyError: "'ConfigBox' object has no attribute 'data_path'"

During handling of the above exception, another exception occurred:

Traceback (most recent call last):
  File "box/box.py", line 503, in box.box.Box.__getitem__
KeyError: 'data_path'

The above exception was the direct cause of the following exception:

Traceback (most recent call last):
  File "box/box.py", line 536, in box.box.Box.__getattr__
  File "box/box.py", line 524, in box.box.Box.__getitem__
box.exceptions.BoxKeyError: "'data_path'"

During handling of the above exception, another exception occurred:

Traceback (most recent call last):
  File "box/box.py", line 538, in box.box.Box.__getattr__
AttributeError: 'ConfigBox' object has no attribute 'data_path'

The above exception was the direct cause of the following exception:

Traceback (most recent call last):
  File "main.py", line 33, in <module>
    data_transformation.main()
  File "/Users/pardhu/Documents/ML_Projects/NLP_Text_Summarizer/src/textSummarizer/pipeline/stage_03_data_transformation.py", line 12, in main
    data_transformation_config = config.get_data_transformation_config()
  File "/Users/pardhu/Documents/ML_Projects/NLP_Text_Summarizer/src/textSummarizer/config/configuration.py", line 54, in get_data_transformation_config
    data_path=config.data_path,
  File "box/config_box.py", line 30, in box.config_box.ConfigBox.__getattr__
  File "box/box.py", line 552, in box.box.Box.__getattr__
box.exceptions.BoxKeyError: "'ConfigBox' object has no attribute 'data_path'"
[2024-02-24 16:12:50,654: INFO: config: PyTorch version 2.2.0 available.]
[2024-02-24 16:12:51,060: INFO: main: >>>>>> stage Data Ingestion stage started <<<<<<]
[2024-02-24 16:12:51,064: INFO: common: yaml file: config/config.yaml loaded successfully]
[2024-02-24 16:12:51,069: INFO: common: yaml file: params.yaml loaded successfully]
[2024-02-24 16:12:51,071: INFO: common: created directory at: artifacts]
[2024-02-24 16:12:51,071: INFO: common: created directory at: artifacts/data_ingestion]
[2024-02-24 16:12:55,007: INFO: data_ingestion: artifacts/data_ingestion/data.zip download! with following info: 
Connection: close
Content-Length: 8274362
Cache-Control: max-age=300
Content-Security-Policy: default-src 'none'; style-src 'unsafe-inline'; sandbox
Content-Type: application/zip
ETag: "6067cb05b4d8701b71f8c029f97cd00c5bc1144cb94632e0db74389cc0c2ab84"
Strict-Transport-Security: max-age=31536000
X-Content-Type-Options: nosniff
X-Frame-Options: deny
X-XSS-Protection: 1; mode=block
X-GitHub-Request-Id: DDAE:4C63:740FA8:8B3089:65DA54F4
Accept-Ranges: bytes
Date: Sat, 24 Feb 2024 21:12:52 GMT
Via: 1.1 varnish
X-Served-By: cache-bos4630-BOS
X-Cache: HIT
X-Cache-Hits: 0
X-Timer: S1708809172.225025,VS0,VE1
Vary: Authorization,Accept-Encoding,Origin
Access-Control-Allow-Origin: *
Cross-Origin-Resource-Policy: cross-origin
X-Fastly-Request-ID: 1e0374aa7ab2088cd14b7b5cb23ca8594eb222d8
Expires: Sat, 24 Feb 2024 21:17:52 GMT
Source-Age: 279

]
[2024-02-24 16:12:55,218: INFO: main: >>>>>> stage Data Ingestion stage completed <<<<<<

x==========x]
[2024-02-24 16:12:55,218: INFO: main: >>>>>> stage Data Validation stage started <<<<<<]
[2024-02-24 16:12:55,223: INFO: common: yaml file: config/config.yaml loaded successfully]
[2024-02-24 16:12:55,224: INFO: common: yaml file: params.yaml loaded successfully]
[2024-02-24 16:12:55,225: INFO: common: created directory at: artifacts]
[2024-02-24 16:12:55,225: INFO: common: created directory at: artifacts/data_validation]
[2024-02-24 16:12:55,227: INFO: main: >>>>>> stage Data Validation stage completed <<<<<<

x==========x]
[2024-02-24 16:12:55,227: INFO: main: >>>>>> stage Data Transformation stage started <<<<<<]
[2024-02-24 16:12:55,230: INFO: common: yaml file: config/config.yaml loaded successfully]
[2024-02-24 16:12:55,232: INFO: common: yaml file: params.yaml loaded successfully]
[2024-02-24 16:12:55,232: INFO: common: created directory at: artifacts]
[2024-02-24 16:12:55,232: INFO: common: created directory at: artifacts/data_transformation]
[2024-02-24 16:13:01,387: INFO: main: >>>>>> stage Data Transformation stage completed <<<<<<

x==========x]
